<?xml version="1.0"?>
<robot xmlns:xacro="http://www.ros.org/wiki/xacro" >

    <xacro:include filename="inertial_macros.xacro"/>

    <joint name="camera_pan_joint" type="revolute">
        <parent link="base_link"/>
        <child link="camera_pan"/>
        <origin xyz="0.125 0 0.08" rpy="0 0 0"/>
        <axis xyz="0 0 1"/>
        <limit effort="1000.0" lower="${-pi/2}" upper="${pi/2}" velocity="2.5"/>
        <joint_properties friction="1000" damping="10"/>
    </joint>

    <link name="camera_pan">
        <visual>
            <geometry>
                <box size="0.01 0.01 0.05"/>
            </geometry>
            <material name="black"/>
        </visual>
        <xacro:inertial_box mass="0.05" x="0.01 " y="0.01" z="0.05">
            <origin xyz="${0.01/2} 0 ${0.05/2}" rpy="0 0 0"/>
        </xacro:inertial_box>
    </link>

    <joint name="camera_tilt_joint" type="revolute">
        <parent link="camera_pan"/>
        <child link="camera_tilt"/>
        <origin xyz="0.01 0 0.025" rpy="0 0 0"/>
        <axis xyz="0 1 0"/>
        <limit effort="1000.0" lower="${-pi/2}" upper="${pi/2}" velocity="2.5"/>
        <joint_properties friction="1000" damping="10"/>
    </joint>

    <link name="camera_tilt">
        <visual>
            <geometry>
                <box size="0.01 0.04 0.03"/>
            </geometry>
            <material name="black"/>
        </visual>
        <xacro:inertial_box mass="0.01" x="0.01 " y="0.05" z="0.05">
            <origin xyz="${0.01/2} 0 ${0.05/2}" rpy="0 0 0"/>
        </xacro:inertial_box>
    </link>

    <joint name="camera_link_joint" type="fixed">
        <parent link="camera_tilt"/>
        <child link="camera_link"/>
        <origin xyz="0.01 0 0" rpy="0 0 0"/>
    </joint>

    <link name="camera_link">
        <visual>
            <geometry>
                <box size="0.01 0.03 0.03"/>
            </geometry>
            <material name="red"/>
        </visual>
    </link>


    <joint name="camera_optical_joint" type="fixed">
        <parent link="camera_link"/>
        <child link="camera_link_optical"/>
        <origin xyz="0 0 0" rpy="0 0 0"/>
    </joint>

    <link name="camera_link_optical"></link>



    <gazebo reference="camera_link">
        <material>Gazebo/Black</material>

        <sensor name="camera" type="camera">
            <pose> 0 0 0 0 0 0 </pose>
            <visualize>true</visualize>
            <update_rate>10</update_rate>
            <camera>
                <horizontal_fov>1.089</horizontal_fov>
                <image>
                    <format>R8G8B8</format>
                    <width>640</width>
                    <height>480</height>
                </image>
                <clip>
                    <near>0.05</near>
                    <far>8.0</far>
                </clip>
            </camera>
            <plugin name="camera_controller" filename="libgazebo_ros_camera.so">
                <frame_name>camera_link_optical</frame_name>
            </plugin>
        </sensor>
    </gazebo>

</robot>